<?xml version="1.0" ?>
<!--
    dg5f_left.xacro
    Licensed under the BSD-3-Clause
    Copyright (c) 2025 Tesollo Inc.
    See LICENSE file for details.

    Reference:
    * https://tesollo.com/dg-5f/
-->

<!-- Dynamics and joint properties will be updated later. Please note. -->

<robot name="dg5f_left">

  <link name="left_base_link" />

  <joint name="base_joint" type="fixed">
    <origin xyz="0 0 0" rpy="0 0 0" />
    <parent link="left_base_link" />
    <child link="ll_dg_mount" />
  </joint>

  <link name="ll_dg_mount">
    <inertial>
      <origin xyz="-6.4721E-09 -2.1674E-05 0.0049997" rpy="0.0 0.0 0.0" />
      <inertia ixx="1.0999E-05" ixy="-2.1734E-12" ixz="1.2441E-12" iyy="1.1018E-05" iyz="4.0435E-09" izz="2.0531E-05" />
      <mass value="0.06" />
    </inertial>
    <visual>
      <geometry>
        <mesh filename="$(find dg_description)/meshes/dg5f_left/visual/ll_dg_mount.dae"/>
      </geometry>
    </visual>
    <collision>
      <geometry>
        <mesh filename="$(find dg_description)/meshes/dg5f_left/collision/ll_dg_mount_c.STL"/>
      </geometry>
    </collision>
  </link>

  <link name="ll_dg_base">
    <inertial>
      <origin xyz="-0.00058969 -0.00051381 0.037363" rpy="0.0 0.0 0.0" />
      <inertia ixx="0.00048608" ixy="-1.041E-05" ixz="1.7229E-05" iyy="0.00049085" iyz="5.191E-06" izz="0.00043369" />
      <mass value="0.4" />
    </inertial>
    <visual>
      <origin xyz="0 0 0" rpy="0 0 0" />
      <geometry>
        <mesh filename="$(find dg_description)/meshes/dg5f_left/visual/ll_dg_base.dae" />
      </geometry>
    </visual>
    <collision>
      <origin xyz="0 0 0" rpy="0 0 0" />
      <geometry>
        <mesh filename="$(find dg_description)/meshes/dg5f_left/collision/ll_dg_base_c.STL" />
      </geometry>
    </collision>
  </link>
  <joint name="lj_dg_mount" type="fixed">
    <parent link="ll_dg_mount"/>
    <child link="ll_dg_base"/>
    <origin rpy="0 0 0" xyz="0 0 0.004"/>
  </joint>

  <link name="ll_dg_palm">
    <inertial>
      <origin xyz="-0.0089544 0.00093674 -0.041327" rpy="0.0 0.0 0.0" />
      <inertia ixx="0.00052648" ixy="2.618E-06" ixz="2.2256E-05" iyy="0.00041644" iyz="4.8923E-05" izz="0.00045776" />
      <mass value="0.4" />
    </inertial>
    <visual>
      <origin xyz="0 0 0" rpy="0 0 0" />
      <geometry>
        <mesh filename="$(find dg_description)/meshes/dg5f_left/visual/ll_dg_palm.dae" />
      </geometry>
    </visual>
    <collision>
      <origin xyz="0 0 0" rpy="0 0 0" />
      <geometry>
        <mesh filename="$(find dg_description)/meshes/dg5f_left/collision/ll_dg_palm_c.STL" />
      </geometry>
    </collision>
  </link>
  <joint name="lj_dg_palm" type="fixed">
    <parent link="ll_dg_base"/>
    <child link="ll_dg_palm"/>
    <origin rpy="0 0 0" xyz="0 0 0.0698"/>
  </joint>

  <link name="ll_dg_1_1">
    <inertial>
      <origin xyz="-0.0027531 -0.0025046 0.021473" rpy="0.0 0.0 0.0" />
      <inertia ixx="1.3718E-05" ixy="-1.3824E-09" ixz="-2.4123E-09" iyy="1.2161E-05" iyz="-2.9055E-06" izz="4.2707E-06" />
      <mass value="0.001" />
    </inertial>
    <visual>
      <origin xyz="0 0 0" rpy="0 0 0" />
      <geometry>
        <mesh filename="$(find dg_description)/meshes/dg5f_left/visual/ll_dg_1_1.dae" />
      </geometry>
    </visual>
    <collision>
      <origin xyz="0 0 0" rpy="0 0 0" />
      <geometry>
        <mesh filename="$(find dg_description)/meshes/dg5f_left/collision/ll_dg_1_1_c.STL" />
      </geometry>
    </collision>
  </link>
  <joint name="lj_dg_1_1" type="revolute">
    <origin xyz="-0.0162 -0.019 0.0128" rpy="0.0 0.0 0.0" />
    <parent link="ll_dg_palm" />
    <child link="ll_dg_1_1" />
    <axis xyz="1 0 0" />
    <limit lower="-0.8901179185171081" upper="0.3839724354387525" effort="100.0" velocity="3.141592653589793"/>
  </joint>

  <link name="ll_dg_1_2">
    <inertial>
      <origin xyz="0.00055633 -0.00055633 0.0015001" rpy="0.0 0.0 0.0" />
      <inertia ixx="1.9935E-06" ixy="-3.114E-09" ixz="-1.5774E-07" iyy="1.9935E-06" iyz="-1.5774E-07" izz="1.459E-06" />
      <mass value="0.001" />
    </inertial>
    <visual>
      <origin xyz="0 0 0" rpy="0 0 0" />
      <geometry>
        <mesh filename="$(find dg_description)/meshes/dg5f_left/visual/ll_dg_1_2.dae" />
      </geometry>
    </visual>
    <collision>
      <origin xyz="0 0 0" rpy="0 0 0" />
      <geometry>
        <mesh filename="$(find dg_description)/meshes/dg5f_left/collision/ll_dg_1_2_c.STL" />
      </geometry>
    </collision>
  </link>
  <joint name="lj_dg_1_2" type="revolute">
    <origin xyz="0.04195 0.0 0.0" rpy="0.0 0.0 0.0" />
    <parent link="ll_dg_1_1" />
    <child link="ll_dg_1_2" />
    <axis xyz="0 0 1" />
    <limit lower="-0.005" upper="3.141592653589793" effort="100.0" velocity="3.141592653589793"/>
  </joint>

  <link name="ll_dg_1_3">
    <inertial>
      <origin xyz="4.7446E-06 -2.3008E-05 -0.014842" rpy="0.0 0.0 0.0" />
      <inertia ixx="6.4181E-06" ixy="1.3678E-09" ixz="2.3552E-09" iyy="5.9794E-06" iyz="-3.6014E-07" izz="2.458E-06" />
      <mass value="0.001" />
    </inertial>
    <visual>
      <origin xyz="0 0 0" rpy="0 0 0" />
      <geometry>
        <mesh filename="$(find dg_description)/meshes/dg5f_left/visual/ll_dg_1_3.dae" />
      </geometry>
    </visual>
    <collision>
      <origin xyz="0 0 0" rpy="0 0 0" />
      <geometry>
        <mesh filename="$(find dg_description)/meshes/dg5f_left/collision/ll_dg_1_3_c.STL" />
      </geometry>
    </collision>
  </link>
  <joint name="lj_dg_1_3" type="revolute">
    <origin xyz="0.0 -0.031 0.0" rpy="0.0 0.0 0.0" />
    <parent link="ll_dg_1_2" />
    <child link="ll_dg_1_3" />
    <axis xyz="1 0 0" />
    <limit lower="-1.5707963267948966" upper="0.005" effort="100.0" velocity="3.141592653589793"/>
  </joint>

  <link name="ll_dg_1_4">
    <inertial>
      <origin xyz="-0.00036539 0.0028048 -0.017045" rpy="0.0 0.0 0.0" />
      <inertia ixx="9.8194E-06" ixy="-3.4626E-09" ixz="-3.7813E-07" iyy="9.4915E-06" iyz="-1.5157E-07" izz="2.9391E-06" />
      <mass value="0.001" />
    </inertial>
    <visual>
      <origin xyz="0 0 0" rpy="0 0 0" />
      <geometry>
        <mesh filename="$(find dg_description)/meshes/dg5f_left/visual/ll_dg_1_4.dae" />
      </geometry>
    </visual>
    <collision>
      <origin xyz="0 0 0" rpy="0 0 0" />
      <geometry>
        <mesh filename="$(find dg_description)/meshes/dg5f_left/collision/ll_dg_1_4_c.STL" />
      </geometry>
    </collision>
  </link>
  <joint name="lj_dg_1_4" type="revolute">
    <origin xyz="0.0 -0.0388 0.0" rpy="0.0 0.0 0.0" />
    <parent link="ll_dg_1_3" />
    <child link="ll_dg_1_4" />
    <axis xyz="1 0 0" />
    <limit lower="-1.5707963267948966" upper="0.005" effort="100.0" velocity="3.141592653589793"/>
  </joint>

  <link name="ll_dg_1_tip">
    <inertial>
      <origin xyz="-5.479E-07 0.012157 -0.0038063" rpy="0.0 0.0 0.0" />
      <inertia ixx="1.9895E-07" ixy="3.0731E-11" ixz="2.1191E-12" iyy="2.5698E-07" iyz="-1.3375E-08" izz="3.2445E-07" />
      <mass value="0.001" />
    </inertial>
    <visual>
      <origin xyz="0 0 0" rpy="0 0 0" />
      <geometry>
        <mesh filename="$(find dg_description)/meshes/dg5f_left/visual/ll_dg_1_tip.dae" />
      </geometry>
    </visual>
    <collision>
      <origin xyz="0 0 0" rpy="0 0 0" />
      <geometry>
        <mesh filename="$(find dg_description)/meshes/dg5f_left/collision/ll_dg_1_tip_c.STL" />
      </geometry>
    </collision>
  </link>
  <joint name="lj_dg_1_tip" type="fixed">
    <origin xyz="0.0 -0.047 0.0" rpy="0.0 0.0 0.0" />
    <parent link="ll_dg_1_4" />
    <child link="ll_dg_1_tip" />
  </joint>

  <link name="ll_dg_2_1">
    <inertial>
      <origin xyz="0.00058566 -0.0030007 0.016589" rpy="0.0 0.0 0.0" />
      <inertia ixx="9.5306E-06" ixy="5.3298E-09" ixz="1.8684E-07" iyy="7.0879E-06" iyz="1.1508E-06" izz="6.5541E-06" />
      <mass value="0.001" />
    </inertial>
    <visual>
      <origin xyz="0 0 0" rpy="0 0 0" />
      <geometry>
        <mesh filename="$(find dg_description)/meshes/dg5f_left/visual/ll_dg_2_1.dae" />
      </geometry>
    </visual>
    <collision>
      <origin xyz="0 0 0" rpy="0 0 0" />
      <geometry>
        <mesh filename="$(find dg_description)/meshes/dg5f_left/collision/ll_dg_2_1_c.STL" />
      </geometry>
    </collision>
  </link>
  <joint name="lj_dg_2_1" type="revolute">
    <origin xyz="-0.0071 -0.027 0.0661" rpy="0.0 0.0 0.0" />
    <parent link="ll_dg_palm" />
    <child link="ll_dg_2_1" />
    <axis xyz="1 0 0" />
    <limit lower="-0.6108652381980153" upper="0.4188790204786391" effort="100.0" velocity="3.141592653589793"/>
  </joint>

  <link name="ll_dg_2_2">
    <inertial>
      <origin xyz="4.7446E-06 -2.3008E-05 -0.014842" rpy="0.0 0.0 0.0" />
      <inertia ixx="6.4181E-06" ixy="1.3678E-09" ixz="2.3552E-09" iyy="5.9794E-06" iyz="-3.6014E-07" izz="2.458E-06" />
      <mass value="0.001" />
    </inertial>
    <visual>
      <origin xyz="0 0 0" rpy="0 0 0" />
      <geometry>
        <mesh filename="$(find dg_description)/meshes/dg5f_left/visual/ll_dg_2_2.dae" />
      </geometry>
    </visual>
    <collision>
      <origin xyz="0 0 0" rpy="0 0 0" />
      <geometry>
        <mesh filename="$(find dg_description)/meshes/dg5f_left/collision/ll_dg_2_2_c.STL" />
      </geometry>
    </collision>
  </link>
  <joint name="lj_dg_2_2" type="revolute">
    <origin xyz="0.01765 0.0 0.0265" rpy="0.0 0.0 0.0" />
    <parent link="ll_dg_2_1" />
    <child link="ll_dg_2_2" />
    <axis xyz="0 1 0" />
    <limit lower="-0.0" upper="2.007128639793479" effort="100.0" velocity="3.141592653589793"/>
  </joint>

  <link name="ll_dg_2_3">
    <inertial>
      <origin xyz="4.7446E-06 -2.3008E-05 -0.014842" rpy="0.0 0.0 0.0" />
      <inertia ixx="6.4181E-06" ixy="1.3678E-09" ixz="2.3552E-09" iyy="5.9794E-06" iyz="-3.6014E-07" izz="2.458E-06" />
      <mass value="0.001" />
    </inertial>
    <visual>
      <origin xyz="0 0 0" rpy="0 0 0" />
      <geometry>
        <mesh filename="$(find dg_description)/meshes/dg5f_left/visual/ll_dg_2_3.dae" />
      </geometry>
    </visual>
    <collision>
      <origin xyz="0 0 0" rpy="0 0 0" />
      <geometry>
        <mesh filename="$(find dg_description)/meshes/dg5f_left/collision/ll_dg_2_3_c.STL" />
      </geometry>
    </collision>
  </link>
  <joint name="lj_dg_2_3" type="revolute">
    <origin xyz="0.0 0.0 0.0388" rpy="0.0 0.0 0.0" />
    <parent link="ll_dg_2_2" />
    <child link="ll_dg_2_3" />
    <axis xyz="0 1 0" />
    <limit lower="0.0" upper="1.5707963267948966" effort="100.0" velocity="3.141592653589793"/>
  </joint>

  <link name="ll_dg_2_4">
    <inertial>
      <origin xyz="0.53347 0.86459 -1.5698" rpy="0.0 0.0 0.0" />
      <inertia ixx="1.6592E-06" ixy="-1.8286E-07" ixz="2.1028E-07" iyy="2.3907E-06" iyz="5.9306E-09" izz="2.8592E-06" />
      <mass value="0.001" />
    </inertial>
    <visual>
      <origin xyz="0 0 0" rpy="0 0 0" />
      <geometry>
        <mesh filename="$(find dg_description)/meshes/dg5f_left/visual/ll_dg_2_4.dae" />
      </geometry>
    </visual>
    <collision>
      <origin xyz="0 0 0" rpy="0 0 0" />
      <geometry>
        <mesh filename="$(find dg_description)/meshes/dg5f_left/collision/ll_dg_2_4_c.STL" />
      </geometry>
    </collision>
  </link>
  <joint name="lj_dg_2_4" type="revolute">
    <origin xyz="0.0 0.0 0.0388" rpy="0.0 0.0 0.0" />
    <parent link="ll_dg_2_3" />
    <child link="ll_dg_2_4" />
    <axis xyz="0 1 0" />
    <limit lower="0.0" upper="1.5707963267948966" effort="100.0" velocity="3.141592653589793"/>
  </joint>

  <link name="ll_dg_2_tip">
    <inertial>
      <origin xyz="-5.479E-07 0.012157 -0.0038063" rpy="0.0 0.0 0.0" />
      <inertia ixx="1.9895E-07" ixy="3.0731E-11" ixz="2.1191E-12" iyy="2.5698E-07" iyz="-1.3375E-08" izz="3.2445E-07" />
      <mass value="0.001" />
    </inertial>
    <visual>
      <origin xyz="0 0 0" rpy="0 0 0" />
      <geometry>
        <mesh filename="$(find dg_description)/meshes/dg5f_left/visual/ll_dg_2_tip.dae" />
      </geometry>
    </visual>
    <collision>
      <origin xyz="0 0 0" rpy="0 0 0" />
      <geometry>
        <mesh filename="$(find dg_description)/meshes/dg5f_left/collision/ll_dg_2_tip_c.STL" />
      </geometry>
    </collision>
  </link>
  <joint name="lj_dg_2_tip" type="fixed">
    <origin xyz="0.0 0.0 0.0362" rpy="0.0 0.0 0.0" />
    <parent link="ll_dg_2_4" />
    <child link="ll_dg_2_tip" />
  </joint>

  <link name="ll_dg_3_1">
    <inertial>
      <origin xyz="0.00017703 -0.0031262 0.016394" rpy="0.0 0.0 0.0" />
      <inertia ixx="9.3331E-06" ixy="-3.5383E-08" ixz="1.1315E-07" iyy="6.7817E-06" iyz="1.1589E-06" izz="6.233E-06" />
      <mass value="0.001" />
    </inertial>
    <visual>
      <origin xyz="0 0 0" rpy="0 0 0" />
      <geometry>
        <mesh filename="$(find dg_description)/meshes/dg5f_left/visual/ll_dg_3_1.dae" />
      </geometry>
    </visual>
    <collision>
      <origin xyz="0 0 0" rpy="0 0 0" />
      <geometry>
        <mesh filename="$(find dg_description)/meshes/dg5f_left/collision/ll_dg_3_1_c.STL" />
      </geometry>
    </collision>
  </link>
  <joint name="lj_dg_3_1" type="revolute">
    <origin xyz="-0.0071 -0.0025 0.0701" rpy="0.0 0.0 0.0" />
    <parent link="ll_dg_palm" />
    <child link="ll_dg_3_1" />
    <axis xyz="1 0 0" />
    <limit lower="-0.6108652381980153" upper="0.6108652381980153" effort="100.0" velocity="3.141592653589793"/>
  </joint>

  <link name="ll_dg_3_2">
    <inertial>
      <origin xyz="4.7446E-06 -2.3008E-05 -0.014842" rpy="0.0 0.0 0.0" />
      <inertia ixx="6.4181E-06" ixy="1.3678E-09" ixz="2.3552E-09" iyy="5.9794E-06" iyz="-3.6014E-07" izz="2.458E-06" />
      <mass value="0.001" />
    </inertial>
    <visual>
      <origin xyz="0 0 0" rpy="0 0 0" />
      <geometry>
        <mesh filename="$(find dg_description)/meshes/dg5f_left/visual/ll_dg_3_2.dae" />
      </geometry>
    </visual>
    <collision>
      <origin xyz="0 0 0" rpy="0 0 0" />
      <geometry>
        <mesh filename="$(find dg_description)/meshes/dg5f_left/collision/ll_dg_3_2_c.STL" />
      </geometry>
    </collision>
  </link>
  <joint name="lj_dg_3_2" type="revolute">
    <origin xyz="0.01765 0.0 0.0265" rpy="0.0 0.0 0.0" />
    <parent link="ll_dg_3_1" />
    <child link="ll_dg_3_2" />
    <axis xyz="0 1 0" />
    <limit lower="0.0" upper="1.9547687622336491" effort="100.0" velocity="3.141592653589793"/>
  </joint>

  <link name="ll_dg_3_3">
    <inertial>
      <origin xyz="4.7446E-06 -2.3008E-05 -0.014842" rpy="0.0 0.0 0.0" />
      <inertia ixx="6.4181E-06" ixy="1.3678E-09" ixz="2.3552E-09" iyy="5.9794E-06" iyz="-3.6014E-07" izz="2.458E-06" />
      <mass value="0.001" />
    </inertial>
    <visual>
      <origin xyz="0 0 0" rpy="0 0 0" />
      <geometry>
        <mesh filename="$(find dg_description)/meshes/dg5f_left/visual/ll_dg_3_3.dae" />
      </geometry>
    </visual>
    <collision>
      <origin xyz="0 0 0" rpy="0 0 0" />
      <geometry>
        <mesh filename="$(find dg_description)/meshes/dg5f_left/collision/ll_dg_3_3_c.STL" />
      </geometry>
    </collision>
  </link>
  <joint name="lj_dg_3_3" type="revolute">
    <origin xyz="0.0 0.0 0.0388" rpy="0.0 0.0 0.0" />
    <parent link="ll_dg_3_2" />
    <child link="ll_dg_3_3" />
    <axis xyz="0 1 0" />
    <limit lower="0.0" upper="1.5707963267948966" effort="100.0" velocity="3.141592653589793"/>
  </joint>

  <link name="ll_dg_3_4">
    <inertial>
      <origin xyz="0.53347 0.86459 -1.5698" rpy="0.0 0.0 0.0" />
      <inertia ixx="1.6592E-06" ixy="-1.8286E-07" ixz="2.1028E-07" iyy="2.3907E-06" iyz="5.9306E-09" izz="2.8592E-06" />
      <mass value="0.001" />
    </inertial>
    <visual>
      <origin xyz="0 0 0" rpy="0 0 0" />
      <geometry>
        <mesh filename="$(find dg_description)/meshes/dg5f_left/visual/ll_dg_3_4.dae" />
      </geometry>
    </visual>
    <collision>
      <origin xyz="0 0 0" rpy="0 0 0" />
      <geometry>
        <mesh filename="$(find dg_description)/meshes/dg5f_left/collision/ll_dg_3_4_c.STL" />
      </geometry>
    </collision>
  </link>
  <joint name="lj_dg_3_4" type="revolute">
    <origin xyz="0.0 0.0 0.0388" rpy="0.0 0.0 0.0" />
    <parent link="ll_dg_3_3" />
    <child link="ll_dg_3_4" />
    <axis xyz="0 1 0" />
    <limit lower="0.0" upper="1.5707963267948966" effort="100.0" velocity="3.141592653589793"/>
  </joint>

  <link name="ll_dg_3_tip">
    <inertial>
      <origin xyz="-5.479E-07 0.012157 -0.0038063" rpy="0.0 0.0 0.0" />
      <inertia ixx="1.9895E-07" ixy="3.0731E-11" ixz="2.1191E-12" iyy="2.5698E-07" iyz="-1.3375E-08" izz="3.2445E-07" />
      <mass value="0.001" />
    </inertial>
    <visual>
      <origin xyz="0 0 0" rpy="0 0 0" />
      <geometry>
        <mesh filename="$(find dg_description)/meshes/dg5f_left/visual/ll_dg_3_tip.dae" />
      </geometry>
    </visual>
    <collision>
      <origin xyz="0 0 0" rpy="0 0 0" />
      <geometry>
        <mesh filename="$(find dg_description)/meshes/dg5f_left/collision/ll_dg_3_tip_c.STL" />
      </geometry>
    </collision>
  </link>
  <joint name="lj_dg_3_tip" type="fixed">
    <origin xyz="0.0 0.0 0.0362" rpy="0.0 0.0 0.0" />
    <parent link="ll_dg_3_4" />
    <child link="ll_dg_3_tip" />
  </joint>

  <link name="ll_dg_4_1">
    <inertial>
      <origin xyz="-0.000244168199391343 -0.00300090352846777 0.0165889702832435" rpy="0.0 0.0 0.0" />
      <inertia ixx="9.53048569995863E-06" ixy="-7.60720623853034E-08" ixz="3.92935984210436E-08" iyy="7.08766686657591E-06" iyz="1.15069967567424E-06" izz="6.55379378472262E-06" />
      <mass value="0.001" />
    </inertial>
    <visual>
      <origin xyz="0 0 0" rpy="0 0 0" />
      <geometry>
        <mesh filename="$(find dg_description)/meshes/dg5f_left/visual/ll_dg_4_1.dae" />
      </geometry>
    </visual>
    <collision>
      <origin xyz="0 0 0" rpy="0 0 0" />
      <geometry>
        <mesh filename="$(find dg_description)/meshes/dg5f_left/collision/ll_dg_4_1_c.STL" />
      </geometry>
    </collision>
  </link>
  <joint name="lj_dg_4_1" type="revolute">
    <origin xyz="-0.0071 0.022 0.0621" rpy="0.0 0.0 0.0" />
    <parent link="ll_dg_palm" />
    <child link="ll_dg_4_1" />
    <axis xyz="1 0 0" />
    <limit lower="-0.4188790204786391" upper="0.6108652381980153" effort="100.0" velocity="3.141592653589793"/>
  </joint>

  <link name="ll_dg_4_2">
    <inertial>
      <origin xyz="4.7446E-06 -2.3008E-05 -0.014842" rpy="0.0 0.0 0.0" />
      <inertia ixx="6.4181E-06" ixy="1.3678E-09" ixz="2.3552E-09" iyy="5.9794E-06" iyz="-3.6014E-07" izz="2.458E-06" />
      <mass value="0.001" />
    </inertial>
    <visual>
      <origin xyz="0 0 0" rpy="0 0 0" />
      <geometry>
        <mesh filename="$(find dg_description)/meshes/dg5f_left/visual/ll_dg_4_2.dae" />
      </geometry>
    </visual>
    <collision>
      <origin xyz="0 0 0" rpy="0 0 0" />
      <geometry>
        <mesh filename="$(find dg_description)/meshes/dg5f_left/collision/ll_dg_4_2_c.STL" />
      </geometry>
    </collision>
  </link>
  <joint name="lj_dg_4_2" type="revolute">
    <origin xyz="0.01765 0.0 0.0265" rpy="0.0 0.0 0.0" />
    <parent link="ll_dg_4_1" />
    <child link="ll_dg_4_2" />
    <axis xyz="0 1 0" />
    <limit lower="0.0" upper="1.9024088846738192" effort="100.0" velocity="3.141592653589793"/>
  </joint>

  <link name="ll_dg_4_3">
    <inertial>
      <origin xyz="4.7446E-06 -2.3008E-05 -0.014842" rpy="0.0 0.0 0.0" />
      <inertia ixx="6.4181E-06" ixy="1.3678E-09" ixz="2.3552E-09" iyy="5.9794E-06" iyz="-3.6014E-07" izz="2.458E-06" />
      <mass value="0.001" />
    </inertial>
    <visual>
      <origin xyz="0 0 0" rpy="0 0 0" />
      <geometry>
        <mesh filename="$(find dg_description)/meshes/dg5f_left/visual/ll_dg_4_3.dae" />
      </geometry>
    </visual>
    <collision>
      <origin xyz="0 0 0" rpy="0 0 0" />
      <geometry>
        <mesh filename="$(find dg_description)/meshes/dg5f_left/collision/ll_dg_4_3_c.STL" />
      </geometry>
    </collision>
  </link>
  <joint name="lj_dg_4_3" type="revolute">
    <origin xyz="0.0 0.0 0.0388" rpy="0.0 0.0 0.0" />
    <parent link="ll_dg_4_2" />
    <child link="ll_dg_4_3" />
    <axis xyz="0 1 0" />
    <limit lower="0.0" upper="1.5707963267948966" effort="100.0" velocity="3.141592653589793"/>
  </joint>

  <link name="ll_dg_4_4">
    <inertial>
      <origin xyz="0.53347 0.86459 -1.5698" rpy="0.0 0.0 0.0" />
      <inertia ixx="1.6592E-06" ixy="-1.8286E-07" ixz="2.1028E-07" iyy="2.3907E-06" iyz="5.9306E-09" izz="2.8592E-06" />
      <mass value="0.001" />
    </inertial>
    <visual>
      <origin xyz="0 0 0" rpy="0 0 0" />
      <geometry>
        <mesh filename="$(find dg_description)/meshes/dg5f_left/visual/ll_dg_4_4.dae" />
      </geometry>
    </visual>
    <collision>
      <origin xyz="0 0 0" rpy="0 0 0" />
      <geometry>
        <mesh filename="$(find dg_description)/meshes/dg5f_left/collision/ll_dg_4_4_c.STL" />
      </geometry>
    </collision>
  </link>
  <joint name="lj_dg_4_4" type="revolute">
    <origin xyz="0.0 0.0 0.0388" rpy="0.0 0.0 0.0" />
    <parent link="ll_dg_4_3" />
    <child link="ll_dg_4_4" />
    <axis xyz="0 1 0" />
    <limit lower="0.0" upper="1.5707963267948966" effort="100.0" velocity="3.141592653589793"/>
  </joint>

  <link name="ll_dg_4_tip">
    <inertial>
      <origin xyz="-5.479E-07 0.012157 -0.0038063" rpy="0.0 0.0 0.0" />
      <inertia ixx="1.9895E-07" ixy="3.0731E-11" ixz="2.1191E-12" iyy="2.5698E-07" iyz="-1.3375E-08" izz="3.2445E-07" />
      <mass value="0.001" />
    </inertial>
    <visual>
      <origin xyz="0 0 0" rpy="0 0 0" />
      <geometry>
        <mesh filename="$(find dg_description)/meshes/dg5f_left/visual/ll_dg_4_tip.dae" />
      </geometry>
    </visual>
    <collision>
      <origin xyz="0 0 0" rpy="0 0 0" />
      <geometry>
        <mesh filename="$(find dg_description)/meshes/dg5f_left/collision/ll_dg_4_tip_c.STL" />
      </geometry>
    </collision>
  </link>
  <joint name="lj_dg_4_tip" type="fixed">
    <origin xyz="0.0 0.0 0.0362" rpy="0.0 0.0 0.0" />
    <parent link="ll_dg_4_4" />
    <child link="ll_dg_4_tip" />
  </joint>

  <link name="ll_dg_5_1">
    <inertial>
      <origin xyz="-0.0029843 0.0071287 -0.022325" rpy="0.0 0.0 0.0" />
      <inertia ixx="2.3655E-05" ixy="2.0571E-07" ixz="-4.4786E-06" iyy="2.3621E-05" iyz="-2.5894E-06" izz="1.1298E-05" />
      <mass value="0.001" />
    </inertial>
    <visual>
      <origin xyz="0 0 0" rpy="0 0 0" />
      <geometry>
        <mesh filename="$(find dg_description)/meshes/dg5f_left/visual/ll_dg_5_1.dae" />
      </geometry>
    </visual>
    <collision>
      <origin xyz="0 0 0" rpy="0 0 0" />
      <geometry>
        <mesh filename="$(find dg_description)/meshes/dg5f_left/collision/ll_dg_5_1_c.STL" />
      </geometry>
    </collision>
  </link>
  <joint name="lj_dg_5_1" type="revolute">
    <origin xyz="0.0103 0.0195 0.0182" rpy="0.0 0.0 0.0" />
    <parent link="ll_dg_palm" />
    <child link="ll_dg_5_1" />
    <axis xyz="0 0 1" />
    <limit lower="-1.0471975511965976" upper="0.017453292519943295" effort="100.0" velocity="3.141592653589793"/>
  </joint>

  <link name="ll_dg_5_2">
    <inertial>
      <origin xyz="0.00055633 -0.00055633 0.0015001" rpy="0.0 0.0 0.0" />
      <inertia ixx="1.9935E-06" ixy="-3.114E-09" ixz="-1.5774E-07" iyy="1.9935E-06" iyz="-1.5774E-07" izz="1.459E-06" />
      <mass value="0.001" />
    </inertial>
    <visual>
      <origin xyz="0 0 0" rpy="0 0 0" />
      <geometry>
        <mesh filename="$(find dg_description)/meshes/dg5f_left/visual/ll_dg_5_2.dae" />
      </geometry>
    </visual>
    <collision>
      <origin xyz="0 0 0" rpy="0 0 0" />
      <geometry>
        <mesh filename="$(find dg_description)/meshes/dg5f_left/collision/ll_dg_5_2_c.STL" />
      </geometry>
    </collision>
  </link>
  <joint name="lj_dg_5_2" type="revolute">
    <origin xyz="0.0 0.028 0.0381" rpy="0.0 0.0 0.0" />
    <parent link="ll_dg_5_1" />
    <child link="ll_dg_5_2" />
    <axis xyz="1 0 0" />
    <limit lower="-0.6108652381980153" upper="0.4188790204786391" effort="100.0" velocity="3.141592653589793"/>
  </joint>

  <link name="ll_dg_5_3">
    <inertial>
      <origin xyz="4.7446E-06 -2.3008E-05 -0.014842" rpy="0.0 0.0 0.0" />
      <inertia ixx="6.4181E-06" ixy="1.3678E-09" ixz="2.3552E-09" iyy="5.9794E-06" iyz="-3.6014E-07" izz="2.458E-06" />
      <mass value="0.001" />
    </inertial>
    <visual>
      <origin xyz="0 0 0" rpy="0 0 0" />
      <geometry>
        <mesh filename="$(find dg_description)/meshes/dg5f_left/visual/ll_dg_5_3.dae" />
      </geometry>
    </visual>
    <collision>
      <origin xyz="0 0 0" rpy="0 0 0" />
      <geometry>
        <mesh filename="$(find dg_description)/meshes/dg5f_left/collision/ll_dg_5_3_c.STL" />
      </geometry>
    </collision>
  </link>
  <joint name="lj_dg_5_3" type="revolute">
    <origin xyz="0.0 0.0 0.031" rpy="0.0 0.0 0.0" />
    <parent link="ll_dg_5_2" />
    <child link="ll_dg_5_3" />
    <axis xyz="0 1 0" />
    <limit lower="-0.005" upper="1.5707963267948966" effort="100.0" velocity="3.141592653589793"/>
  </joint>

  <link name="ll_dg_5_4">
    <inertial>
      <origin xyz="-0.000365388872256699 0.00280482111063283 -0.0170446706549657" rpy="0.0 0.0 0.0" />
      <inertia ixx="9.81936385229634E-06" ixy="-3.46258177073586E-09" ixz="-3.78130201155673E-07" iyy="9.49149264777596E-06" iyz="-1.51572680457629E-07" izz="2.93905089746508E-06" />
      <mass value="0.001" />
    </inertial>
    <visual>
      <origin xyz="0 0 0" rpy="0 0 0" />
      <geometry>
        <mesh filename="$(find dg_description)/meshes/dg5f_left/visual/ll_dg_5_4.dae" />
      </geometry>
    </visual>
    <collision>
      <origin xyz="0 0 0" rpy="0 0 0" />
      <geometry>
        <mesh filename="$(find dg_description)/meshes/dg5f_left/collision/ll_dg_5_4_c.STL" />
      </geometry>
    </collision>
  </link>
  <joint name="lj_dg_5_4" type="revolute">
    <origin xyz="0.0 0.0 0.0388" rpy="0.0 0.0 0.0" />
    <parent link="ll_dg_5_3" />
    <child link="ll_dg_5_4" />
    <axis xyz="0 1 0" />
    <limit lower="-0.005" upper="1.5707963267948966" effort="100.0" velocity="3.141592653589793"/>
  </joint>

  <link name="ll_dg_5_tip">
    <inertial>
      <origin xyz="-5.47903832567864E-07 0.0121569905128545 -0.00380629104982077" rpy="0.0 0.0 0.0" />
      <inertia ixx="1.98954959099337E-07" ixy="3.07311777374764E-11" ixz="2.11907398080508E-12" iyy="2.56982145081983E-07" iyz="-1.33749332188622E-08" izz="3.24447323464712E-07" />
      <mass value="0.001" />
    </inertial>
    <visual>
      <origin xyz="0 0 0" rpy="0 0 0" />
      <geometry>
        <mesh filename="$(find dg_description)/meshes/dg5f_left/visual/ll_dg_5_tip.dae" />
      </geometry>
    </visual>
    <collision>
      <origin xyz="0 0 0" rpy="0 0 0" />
      <geometry>
        <mesh filename="$(find dg_description)/meshes/dg5f_left/collision/ll_dg_5_tip_c.STL" />
      </geometry>
    </collision>
  </link>
  <joint name="lj_dg_5_tip" type="fixed">
    <origin xyz="0.0 0.0 0.047" rpy="0.0 0.0 0.0" />
    <parent link="ll_dg_5_4" />
    <child link="ll_dg_5_tip" />
  </joint>
</robot>
